<?xml version="1.0" encoding="UTF-8"?>
<!-- Generated by org.testng.reporters.JUnitReportReporter -->
<testsuite hostname="LAPTOP-5COFNKBT" failures="1" tests="4" name="com.nit.dp.Dpproject" time="126.173" errors="0" timestamp="19 Oct 2024 10:09:09 GMT" skipped="3">
  <testcase classname="com.nit.dp.Dpproject" name="retryAnalyzer" time="38.934">
    <failure message="expected [false] but found [true]" type="java.lang.AssertionError">
      <![CDATA[java.lang.AssertionError: expected [false] but found [true]at org.testng.Assert.fail(Assert.java:96)at org.testng.Assert.failNotEquals(Assert.java:776)at org.testng.Assert.assertFalse(Assert.java:65)at org.testng.Assert.assertFalse(Assert.java:75)at com.nit.dp.Dpproject.retryAnalyzer(Dpproject.java:76)at java.base/jdk.internal.reflect.NativeMethodAccessorImpl.invoke0(Native Method)at java.base/jdk.internal.reflect.NativeMethodAccessorImpl.invoke(NativeMethodAccessorImpl.java:77)at java.base/jdk.internal.reflect.DelegatingMethodAccessorImpl.invoke(DelegatingMethodAccessorImpl.java:43)at java.base/java.lang.reflect.Method.invoke(Method.java:568)at org.testng.internal.MethodInvocationHelper.invokeMethod(MethodInvocationHelper.java:124)at org.testng.internal.Invoker.invokeMethod(Invoker.java:571)at org.testng.internal.Invoker.retryFailed(Invoker.java:829)at org.testng.internal.Invoker.invokeTestMethods(Invoker.java:1000)at org.testng.internal.TestMethodWorker.invokeTestMethods(TestMethodWorker.java:125)at org.testng.internal.TestMethodWorker.run(TestMethodWorker.java:109)at org.testng.TestRunner.privateRun(TestRunner.java:648)at org.testng.TestRunner.run(TestRunner.java:505)at org.testng.SuiteRunner.runTest(SuiteRunner.java:455)at org.testng.SuiteRunner.runSequentially(SuiteRunner.java:450)at org.testng.SuiteRunner.privateRun(SuiteRunner.java:415)at org.testng.SuiteRunner.run(SuiteRunner.java:364)at org.testng.SuiteRunnerWorker.runSuite(SuiteRunnerWorker.java:52)at org.testng.SuiteRunnerWorker.run(SuiteRunnerWorker.java:84)at org.testng.TestNG.runSuitesSequentially(TestNG.java:1187)at org.testng.TestNG.runSuitesLocally(TestNG.java:1116)at org.testng.TestNG.runSuites(TestNG.java:1028)at org.testng.TestNG.run(TestNG.java:996)at org.testng.remote.AbstractRemoteTestNG.run(AbstractRemoteTestNG.java:115)at org.testng.remote.RemoteTestNG.initAndRun(RemoteTestNG.java:251)at org.testng.remote.RemoteTestNG.main(RemoteTestNG.java:77)]]>
    </failure>
  </testcase> <!-- retryAnalyzer -->
  <testcase classname="com.nit.dp.Dpproject" name="retryAnalyzer" time="36.323">
    <skipped/>
  </testcase> <!-- retryAnalyzer -->
  <testcase classname="com.nit.dp.Dpproject" name="retryAnalyzer" time="27.387">
    <skipped/>
  </testcase> <!-- retryAnalyzer -->
  <testcase classname="com.nit.dp.Dpproject" name="retryAnalyzer" time="23.529">
    <skipped/>
  </testcase> <!-- retryAnalyzer -->
</testsuite> <!-- com.nit.dp.Dpproject -->
